<mujoco model="arm3d">
  <compiler angle="radian" coordinate="local" inertiafromgeom="true"></compiler>
  <option gravity="0 0 0" integrator="Euler" iterations="20" timestep="0.01"></option>
  <default>
    <joint armature="0.04" damping="1" limited="true"></joint>
    <geom conaffinity="0" condim="1" contype="0" density="300" friction=".8 .1 .1" margin="0.002"></geom>
  </default>
  <worldbody>
    <light diffuse=".5 .5 .5" dir="0 0 -1" pos="0 0 3"></light>
    <geom conaffinity="1" contype="1" name="table" pos="0 0.5 -0.5" size="1 1 0.1" type="plane"></geom>
    <!-- <geom name="wall" rgba="1 0 0 1" type="box" pos="0 1. -0.325" size="1 0.03 1" contype="1" conaffinity="1"/> -->
    <!-- <body name="0_x_slide_link" pos="0 -0.6 0"> -->
    <!--   <geom fromto="-0.1 0 -0.4 0.1 0 -0.4" name="0_sp0" rgba="0.6 0.6 0.6 1" size="0.1" type="capsule"></geom> -->
    <!--   <joint axis="1 0 0" name="0_x_slide" pos="0 0 -0.4" range="-1.0 1.0" type="slide"></joint> -->
    <body name="0_y_slide_link" pos="0 -0.6 0">
      <geom fromto="0 -0.1 -0.4 0 0.1 -0.4" name="0_sp1" rgba="0.6 0.6 0.6 1" size="0.1" type="capsule"></geom>
      <joint axis="0 1 0" name="0_y_slide" pos="0 0 -0.4" range="-1.0 1.0" type="slide"></joint>
      <body name="0_r_shoulder_pan_link" pos="0 0 0">
        <geom name="0_e1" pos="-0.06 0.05 0.2" rgba="0.6 0.6 0.6 1" size="0.05" type="sphere"></geom>
        <geom name="0_e2" pos=" 0.06 0.05 0.2" rgba="0.6 0.6 0.6 1" size="0.05" type="sphere"></geom>
        <geom name="0_e1p" pos="-0.06 0.09 0.2" rgba="0.1 0.1 0.1 1" size="0.03" type="sphere"></geom>
        <geom name="0_e2p" pos=" 0.06 0.09 0.2" rgba="0.1 0.1 0.1 1" size="0.03" type="sphere"></geom>
        <geom name="0_e1pp" pos="-0.06 0.13 0.2" rgba="0.1 0.1 0.1 1" size="0.01" type="sphere"></geom>
        <geom name="0_target0" pos="0 0.1 -0.3" rgba="1 0 0 1" size="0.02" type="sphere"></geom>
        <geom name="0_target1" pos="0.15 0.1 0" rgba="1 0 0 1" size="0.02" type="sphere"></geom>
        <geom name="0_target2" pos="-0.15 0.1 0" rgba="1 0 0 1" size="0.02" type="sphere"></geom>
        <geom fromto="0 0 -0.4 0 0 0.2" name="0_sp" size="0.1" type="capsule"></geom>
        <joint axis="0 0 1" damping="1.0" name="0_r_shoulder_pan_joint" pos="0 0 0" range="-2.2854 1.714602" type="hinge"></joint>
        <body axisangle="1 0 0 -1.0" name="0_r_shoulder_lift_link" pos="0 0 0">
          <geom fromto="-0.15 0 0 0.15 0 0" name="0_sl" size="0.1" type="capsule"></geom>
          <joint axis="1 0 0" damping="1.0" name="0_r_shoulder_lift_joint" pos="0.3 0 0" range="-0.2 2.2" type="hinge"></joint>
          <body axisangle="0 0 1 1.57079" name="0_r_shoulder_turn_link" pos="0.3 0 0">
            <geom name="0_st" pos="0 0 0" size="0.1" type="sphere"></geom>
            <joint axis="0 0 1" damping="1.0" name="0_r_shoulder_turn_joint" pos="0 0 0" range="-1.57079 0.4" type="hinge"></joint>
            <body name="0_r_upper_arm_roll_link" pos="0 0 0">
              <geom fromto="-0.1 0 0 0.1 0 0" name="0_uar" size="0.02" type="capsule"></geom>
              <joint axis="1 0 0" damping="0.1" name="0_r_upper_arm_roll_joint" pos="0 0 0" range="-1.5 1.7" type="hinge"></joint>
              <body name="0_r_upper_arm_link" pos="0 0 0">
                <geom fromto="0 0 0 0.4 0 0" name="0_ua" size="0.06" type="capsule"></geom>
                <body axisangle="0 1 0 -1.65" name="0_r_elbow_flex_link" pos="0.4 0 0">
                  <geom fromto="0 -0.02 0 0.0 0.02 0" name="0_ef" size="0.06" type="capsule"></geom>
                  <joint axis="0 1 0" damping="0.1" name="0_r_elbow_flex_joint" pos="0 0 0" range="-0.6713 1.65" type="hinge"></joint>
                  <body name="0_r_forearm_roll_link" pos="0 0 0">
                    <geom fromto="-0.1 0 0 0.1 0 0" name="0_fr" size="0.02" type="capsule"></geom>
                    <joint axis="1 0 0" damping=".1" limited="true" name="0_r_forearm_roll_joint" pos="0 0 0" range="-1.5 1.5" type="hinge"></joint>
                    <body name="0_r_forearm_link" pos="0 0 0">
                      <geom fromto="0 0 0 0.291 0 0" name="0_fa" size="0.05" type="capsule"></geom>
                      <body name="0_r_wrist_flex_link" pos="0.321 0 0">
                        <geom fromto="0 -0.02 0 0 0.02 0" name="0_wf" size="0.01" type="capsule"></geom>
                        <joint axis="0 1 0" damping=".1" name="0_r_wrist_flex_joint" pos="0 0 0" range="-1.094 0" type="hinge"></joint>
                        <body name="0_r_wrist_roll_link" pos="0 0 0">
                          <joint axis="1 0 0" damping="0.1" limited="true" name="0_r_wrist_roll_joint" pos="0 0 0" range="-1.5 1.5" type="hinge"></joint>
                          <body name="0_tips_arm" pos="0 0 0"><!-- <geom name="tip_arml" type="sphere" pos="0.1 -0.1 0." size="0.01" /> --><!--<body name="sword" pos="0.1 0 0.5" >  Adjust position as needed --><!--    <geom name="sword_blade" type="box" size="0.01 0.005 0.5" conaffinity="1"/>  Adjust size and shape as needed --><!--    <geom name="sword_handle" type="box" size="0.02 0.02 0.1"  pos="0 0 -0.5"/>  Handle, adjust position relative to blade --><!--</body> --><!-- <geom name="tip_armr" type="sphere" pos="0.1 0.1 0." size="0.01" /> --></body>
                          <geom conaffinity="1" name="0_sword_blade" pos="0.6 0.02 0.02" size="0.5 0.005 0.01" type="box"></geom>
                          <!-- Adjust size and shape as needed-->
                          <geom conaffinity="1" name="0_sword_handle" pos="0.1 0.02 0.02" size="0.1 0.02 0.02" type="box"></geom>
                          <!--Handle, adjust position relative to blade -->
                          <!-- <geom type="capsule" fromto="0 -0.1 0. 0.0 +0.1 0" size="0.02" contype="1" conaffinity="1" />
                      <geom type="capsule" fromto="0 -0.1 0. 0.1 -0.1 0" size="0.02" contype="1" conaffinity="1" />
                      <geom type="capsule" fromto="0 +0.1 0. 0.1 +0.1 0." size="0.02" contype="1" conaffinity="1" /> -->
                        </body>
                      </body>
                    </body>
                  </body>
                </body>
              </body>
            </body>
          </body>
        </body>
      </body>
    </body>
    <!-- </body> -->
    <!-- <body name="goal" pos="0.45 -0.05 -0.3230"> -->
    <!--   <geom conaffinity="0" contype="0" density="0.00001" rgba="1 0 0 1" size="0.08 0.001 0.1" type="cylinder"></geom> -->
    <!--   <joint axis="0 1 0" damping="0.5" name="goal_slidey" pos="0 0 0" range="-10.3213 10.3" type="slide"></joint> -->
    <!--   <joint axis="1 0 0" damping="0.5" name="goal_slidex" pos="0 0 0" range="-10.3213 10.3" type="slide"></joint> -->
    <!-- </body> -->
    <!-- <body name="1_x_slide_link" pos="0 1.6 0" axisangle="0 0 1 -3.1415926" > -->
    <!--   <geom fromto="-0.1 0 -0.4 0.1 0 -0.4" name="1_sp0" rgba="0.6 0.6 0.6 1" size="0.1" type="capsule"></geom> -->
    <!--   <joint axis="1 0 0" name="1_x_slide" pos="0 0 -0.4" range="-1.0 1.0" type="slide"></joint> -->
    <body axisangle="0 0 1 -3.1415926" name="1_y_slide_link" pos="0 1.6 0">
      <geom fromto="0 -0.1 -0.4 0 0.1 -0.4" name="1_sp1" rgba="0.6 0.6 0.6 1" size="0.1" type="capsule"></geom>
      <joint axis="0 1 0" name="1_y_slide" pos="0 0 -0.4" range="-1.0 1.0" type="slide"></joint>
      <body name="1_r_shoulder_pan_link" pos="0 0 0">
        <geom name="1_e1" pos="-0.06 0.05 0.2" rgba="0.6 0.6 0.6 1" size="0.05" type="sphere"></geom>
        <geom name="1_e2" pos=" 0.06 0.05 0.2" rgba="0.6 0.6 0.6 1" size="0.05" type="sphere"></geom>
        <geom name="1_e1p" pos="-0.06 0.09 0.2" rgba="0.1 0.1 0.1 1" size="0.03" type="sphere"></geom>
        <geom name="1_e2p" pos=" 0.06 0.09 0.2" rgba="0.1 0.1 0.1 1" size="0.03" type="sphere"></geom>
        <geom name="1_target0" pos="0 0.1 -0.3" rgba="1 0 0 1" size="0.02" type="sphere"></geom>
        <geom name="1_target1" pos="0.15 0.1 0" rgba="1 0 0 1" size="0.02" type="sphere"></geom>
        <geom name="1_target2" pos="-0.15 0.1 0" rgba="1 0 0 1" size="0.02" type="sphere"></geom>
        <geom fromto="0 0 -0.4 0 0 0.2" name="1_sp" size="0.1" type="capsule"></geom>
        <joint axis="0 0 1" damping="1.0" name="1_r_shoulder_pan_joint" pos="0 0 0" range="-2.2854 1.714602" type="hinge"></joint>
        <body axisangle="1 0 0 -1.0" name="1_r_shoulder_lift_link" pos="0 0 0">
          <geom fromto="-0.15 0 0 0.15 0 0" name="1_sl" size="0.1" type="capsule"></geom>
          <joint axis="1 0 0" damping="1.0" name="1_r_shoulder_lift_joint" pos="0.3 0 0" range="-0.2 2.2" type="hinge"></joint>
          <body axisangle="0 0 1 1.57079" name="1_r_shoulder_turn_link" pos="0.3 0 0">
            <geom name="1_st" pos="0 0 0" size="0.1" type="sphere"></geom>
            <joint axis="0 0 1" damping="1.0" name="1_r_shoulder_turn_joint" pos="0 0 0" range="-1.57079 0.4" type="hinge"></joint>
            <body name="1_r_upper_arm_roll_link" pos="0 0 0">
              <geom fromto="-0.1 0 0 0.1 0 0" name="1_uar" size="0.02" type="capsule"></geom>
              <joint axis="1 0 0" damping="0.1" name="1_r_upper_arm_roll_joint" pos="0 0 0" range="-1.5 1.7" type="hinge"></joint>
              <body name="1_r_upper_arm_link" pos="0 0 0">
                <geom fromto="0 0 0 0.4 0 0" name="1_ua" size="0.06" type="capsule"></geom>
                <body axisangle="0 1 0 -1.65" name="1_r_elbow_flex_link" pos="0.4 0 0">
                  <geom fromto="0 -0.02 0 0.0 0.02 0" name="1_ef" size="0.06" type="capsule"></geom>
                  <joint axis="0 1 0" damping="0.1" name="1_r_elbow_flex_joint" pos="0 0 0" range="-0.6713 1.65" type="hinge"></joint>
                  <body name="1_r_forearm_roll_link" pos="0 0 0">
                    <geom fromto="-0.1 0 0 0.1 0 0" name="1_fr" size="0.02" type="capsule"></geom>
                    <joint axis="1 0 0" damping=".1" limited="true" name="1_r_forearm_roll_joint" pos="0 0 0" range="-1.5 1.5" type="hinge"></joint>
                    <body name="1_r_forearm_link" pos="0 0 0">
                      <geom fromto="0 0 0 0.291 0 0" name="1_fa" size="0.05" type="capsule"></geom>
                      <body name="1_r_wrist_flex_link" pos="0.321 0 0">
                        <geom fromto="0 -0.02 0 0 0.02 0" name="1_wf" size="0.01" type="capsule"></geom>
                        <joint axis="0 1 0" damping=".1" name="1_r_wrist_flex_joint" pos="0 0 0" range="-1.094 0" type="hinge"></joint>
                        <body name="1_r_wrist_roll_link" pos="0 0 0">
                          <joint axis="1 0 0" damping="0.1" limited="true" name="1_r_wrist_roll_joint" pos="0 0 0" range="-1.5 1.5" type="hinge"></joint>
                          <body name="1_tips_arm" pos="0 0 0"><!-- <geom name="tip_arml" type="sphere" pos="0.1 -0.1 0." size="0.01" /> --><!--<body name="sword" pos="0.1 0 0.5" >  Adjust position as needed --><!--    <geom name="sword_blade" type="box" size="0.01 0.005 0.5" conaffinity="1"/>  Adjust size and shape as needed --><!--    <geom name="sword_handle" type="box" size="0.02 0.02 0.1"  pos="0 0 -0.5"/>  Handle, adjust position relative to blade --><!--</body> --><!-- <geom name="tip_armr" type="sphere" pos="0.1 0.1 0." size="0.01" /> --></body>
                          <geom conaffinity="1" name="1_sword_blade" pos="0.6 0.02 0.02" size="0.5 0.005 0.01" type="box"></geom>
                          <!-- Adjust size and shape as needed-->
                          <geom conaffinity="1" name="1_sword_handle" pos="0.1 0.02 0.02" size="0.1 0.02 0.02" type="box"></geom>
                          <!--Handle, adjust position relative to blade -->
                          <!-- <geom type="capsule" fromto="0 -0.1 0. 0.0 +0.1 0" size="0.02" contype="1" conaffinity="1" />
                      <geom type="capsule" fromto="0 -0.1 0. 0.1 -0.1 0" size="0.02" contype="1" conaffinity="1" />
                      <geom type="capsule" fromto="0 +0.1 0. 0.1 +0.1 0." size="0.02" contype="1" conaffinity="1" /> -->
                        </body>
                      </body>
                    </body>
                  </body>
                </body>
              </body>
            </body>
          </body>
        </body>
      </body>
    </body>
    <!-- </body> -->
  </worldbody>
  <actuator>
    <!-- <motor ctrllimited="true" ctrlrange="-2.0 2.0" joint="0_x_slide"></motor> -->
    <motor ctrllimited="true" ctrlrange="-2.0 2.0" joint="0_y_slide"></motor>
    <motor ctrllimited="true" ctrlrange="-2.0 2.0" joint="0_r_shoulder_pan_joint"></motor>
    <motor ctrllimited="true" ctrlrange="-2.0 2.0" joint="0_r_shoulder_lift_joint"></motor>
    <motor ctrllimited="true" ctrlrange="-2.0 2.0" joint="0_r_shoulder_turn_joint"></motor>
    <motor ctrllimited="true" ctrlrange="-2.0 2.0" joint="0_r_upper_arm_roll_joint"></motor>
    <motor ctrllimited="true" ctrlrange="-2.0 2.0" joint="0_r_elbow_flex_joint"></motor>
    <motor ctrllimited="true" ctrlrange="-2.0 2.0" joint="0_r_forearm_roll_joint"></motor>
    <motor ctrllimited="true" ctrlrange="-2.0 2.0" joint="0_r_wrist_flex_joint"></motor>
    <motor ctrllimited="true" ctrlrange="-2.0 2.0" joint="0_r_wrist_roll_joint"></motor>
    <!-- <motor ctrllimited="true" ctrlrange="-2.0 2.0" joint="1_x_slide"></motor> -->
    <motor ctrllimited="true" ctrlrange="-2.0 2.0" joint="1_y_slide"></motor>
    <motor ctrllimited="true" ctrlrange="-2.0 2.0" joint="1_r_shoulder_pan_joint"></motor>
    <motor ctrllimited="true" ctrlrange="-2.0 2.0" joint="1_r_shoulder_lift_joint"></motor>
    <motor ctrllimited="true" ctrlrange="-2.0 2.0" joint="1_r_shoulder_turn_joint"></motor>
    <motor ctrllimited="true" ctrlrange="-2.0 2.0" joint="1_r_upper_arm_roll_joint"></motor>
    <motor ctrllimited="true" ctrlrange="-2.0 2.0" joint="1_r_elbow_flex_joint"></motor>
    <motor ctrllimited="true" ctrlrange="-2.0 2.0" joint="1_r_forearm_roll_joint"></motor>
    <motor ctrllimited="true" ctrlrange="-2.0 2.0" joint="1_r_wrist_flex_joint"></motor>
    <motor ctrllimited="true" ctrlrange="-2.0 2.0" joint="1_r_wrist_roll_joint"></motor>
  </actuator>
  <contact>
    <pair geom1="0_sword_blade" geom2="1_sword_blade" name="blade_contact"></pair>
  </contact>
</mujoco>
