<mujoco model="arm3d">
	<compiler angle="radian" coordinate="local" inertiafromgeom="true" />
	<option gravity="0 0 0" integrator="Euler" iterations="20" timestep="0.01" />
	<default>
		<joint armature="0.04" damping="1" limited="true" />
		<geom conaffinity="0" condim="1" contype="0" density="300" friction=".8 .1 .1" margin="0.002" />
	</default>
	<worldbody>
		<light diffuse=".5 .5 .5" dir="0 0 -1" pos="0 0 3" />
		<geom conaffinity="1" contype="1" name="table" pos="0 0.5 -0.5" size="1 1 0.1" type="plane" />
		<!-- <geom fromto="-0.1 0 -0.4 0.1 0 -0.4" name="0_x_slide" rgba="0.6 0.6 0.6 1" size="0.1" type="capsule"></geom> -->
		<!-- <joint axis="1 0 0" name="0_x_slide_joint" pos="0 0 -0.4" range="-1.0 1.0" type="slide"></joint> -->
		<body name="0_y_slide_link" pos="0 -0.6 0">
			<geom fromto="0 -0.1 -0.4 0 0.1 -0.4" name="0_y_slide" rgba="0.6 0.6 0.6 1" size="0.1" type="capsule" />
			<joint axis="0 1 0" name="0_y_slide_joint" pos="0 0 -0.4" range="-1.0 1.0" type="slide" />
			<body name="0_r_shoulder_pan_link" pos="0 0 0">
				<geom name="0_l_eye" pos="-0.06 0.05 0.2" rgba="0.6 0.6 0.6 1" size="0.05" type="sphere" />
				<geom name="0_r_eye" pos=" 0.06 0.05 0.2" rgba="0.6 0.6 0.6 1" size="0.05" type="sphere" />
				<geom name="0_l_eye_pin" pos="-0.06 0.09 0.2" rgba="0.1 0.1 0.1 1" size="0.03" type="sphere" />
				<geom name="0_r_eye_pin" pos=" 0.06 0.09 0.2" rgba="0.1 0.1 0.1 1" size="0.03" type="sphere" />
				<geom name="0_target0" pos="0 0.1 -0.3" rgba="1 0 0 1" size="0.02" type="sphere" />
				<geom name="0_target1" pos="0.15 0.1 0" rgba="1 0 0 1" size="0.02" type="sphere" />
				<geom name="0_target2" pos="-0.15 0.1 0" rgba="1 0 0 1" size="0.02" type="sphere" />
				<geom fromto="0 0 -0.4 0 0 0.2" name="0_shoulder_pan" size="0.1" type="capsule" />
				<joint axis="0 0 1" damping="1.0" name="0_r_shoulder_pan_joint" pos="0 0 0" range="-2.2854 1.714602" type="hinge" />
				<body axisangle="1 0 0 -1.0" name="0_r_shoulder_lift_link" pos="0 0 0">
					<geom fromto="-0.15 0 0 0.15 0 0" name="0_shoulder_lift" size="0.1" type="capsule" />
					<joint axis="1 0 0" damping="1.0" name="0_r_shoulder_lift_joint" pos="0.3 0 0" range="-0.2 2.2" type="hinge" />
					<body axisangle="0 0 1 1.57079" name="0_r_shoulder_turn_link" pos="0.3 0 0">
						<geom name="0_shoulder_turn" pos="0 0 0" size="0.1" type="sphere" />
						<joint axis="0 0 1" damping="1.0" name="0_r_shoulder_turn_joint" pos="0 0 0" range="-1.57079 0.4" type="hinge" />
						<body name="0_r_upper_arm_roll_link" pos="0 0 0">
							<geom fromto="-0.1 0 0 0.1 0 0" name="0_upper_arm_roll" size="0.02" type="capsule" />
							<joint axis="1 0 0" damping="0.1" name="0_r_upper_arm_roll_joint" pos="0 0 0" range="-1.5 1.7" type="hinge" />
							<body name="0_r_upper_arm_link" pos="0 0 0">
								<geom fromto="0 0 0 0.4 0 0" name="0_upper_arm" size="0.06" type="capsule" />
								<body axisangle="0 1 0 -1.65" name="0_r_elbow_flex_link" pos="0.4 0 0">
									<geom fromto="0 -0.02 0 0.0 0.02 0" name="0_elbow_flex" size="0.06" type="capsule" />
									<joint axis="0 1 0" damping="0.1" name="0_r_elbow_flex_joint" pos="0 0 0" range="-0.6713 1.65" type="hinge" />
									<body name="0_r_forearm_roll_link" pos="0 0 0">
										<geom fromto="-0.1 0 0 0.1 0 0" name="0_forearm_roll" size="0.02" type="capsule" />
										<joint axis="1 0 0" damping=".1" limited="true" name="0_r_forearm_roll_joint" pos="0 0 0" range="-1.5 1.5" type="hinge" />
										<body name="0_r_forearm_link" pos="0 0 0">
											<geom fromto="0 0 0 0.291 0 0" name="0_forearm" size="0.05" type="capsule" />
											<body name="0_r_wrist_flex_link" pos="0.321 0 0">
												<geom fromto="0 -0.02 0 0 0.02 0" name="0_wrist_flex" size="0.01" type="capsule" />
												<joint axis="0 1 0" damping=".1" name="0_r_wrist_flex_joint" pos="0 0 0" range="-1.094 0" type="hinge" />
												<body name="0_r_wrist_roll_link" pos="0 0 0">
													<joint axis="1 0 0" damping="0.1" limited="true" name="0_r_wrist_roll_joint" pos="0 0 0" range="-1.5 1.5" type="hinge" />
													<geom conaffinity="1" name="0_sword_blade" pos="0.6 0.02 0.02" size="0.5 0.005 0.01" type="box" />
													<geom name="0_sword_tip" type="sphere" rgba="0.6 0.6 0.6 1" pos=" 1.1 0.02 0.02" size="0.008" conaffinity="1" />
													<geom conaffinity="1" name="0_sword_handle" pos="0.1 0.02 0.02" size="0.1 0.02 0.02" type="box" />
												</body>
											</body>
										</body>
									</body>
								</body>
							</body>
						</body>
					</body>
				</body>
			</body>
		</body>
		<!-- <body name="1_x_slide_link" pos="0 1.6 0" axisangle="0 0 1 -3.1415926" > -->
		<!-- <geom fromto="-0.1 0 -0.4 0.1 0 -0.4" name="1_x_slide" rgba="0.6 0.6 0.6 1" size="0.1" type="capsule"></geom> -->
		<!-- <joint axis="1 0 0" name="1_x_slide_joint" pos="0 0 -0.4" range="-1.0 1.0" type="slide"></joint> -->
		<body axisangle="0 0 1 -3.1415926" name="1_y_slide_link" pos="0 1.6 0">
			<geom fromto="0 -0.1 -0.4 0 0.1 -0.4" name="1_y_slide" rgba="0.6 0.6 0.6 1" size="0.1" type="capsule" />
			<joint axis="0 1 0" name="1_y_slide_joint" pos="0 0 -0.4" range="-1.0 1.0" type="slide" />
			<body name="1_r_shoulder_pan_link" pos="0 0 0">
				<geom name="1_l_eye" pos="-0.06 0.05 0.2" rgba="0.6 0.6 0.6 1" size="0.05" type="sphere" />
				<geom name="1_r_eye" pos=" 0.06 0.05 0.2" rgba="0.6 0.6 0.6 1" size="0.05" type="sphere" />
				<geom name="1_l_eye_pin" pos="-0.06 0.09 0.2" rgba="0.1 0.1 0.1 1" size="0.03" type="sphere" />
				<geom name="1_r_eye_pin" pos=" 0.06 0.09 0.2" rgba="0.1 0.1 0.1 1" size="0.03" type="sphere" />
				<geom name="1_target0" pos="0 0.1 -0.3" rgba="1 0 0 1" size="0.02" type="sphere" />
				<geom name="1_target1" pos="0.15 0.1 0" rgba="1 0 0 1" size="0.02" type="sphere" />
				<geom name="1_target2" pos="-0.15 0.1 0" rgba="1 0 0 1" size="0.02" type="sphere" />
				<geom fromto="0 0 -0.4 0 0 0.2" name="1_shoulder_pan" size="0.1" type="capsule" />
				<joint axis="0 0 1" damping="1.0" name="1_r_shoulder_pan_joint" pos="0 0 0" range="-2.2854 1.714602" type="hinge" />
				<body axisangle="1 0 0 -1.0" name="1_r_shoulder_lift_link" pos="0 0 0">
					<geom fromto="-0.15 0 0 0.15 0 0" name="1_shoulder_lift" size="0.1" type="capsule" />
					<joint axis="1 0 0" damping="1.0" name="1_r_shoulder_lift_joint" pos="0.3 0 0" range="-0.2 2.2" type="hinge" />
					<body axisangle="0 0 1 1.57079" name="1_r_shoulder_turn_link" pos="0.3 0 0">
						<geom name="1_shoulder_turn" pos="0 0 0" size="0.1" type="sphere" />
						<joint axis="0 0 1" damping="1.0" name="1_r_shoulder_turn_joint" pos="0 0 0" range="-1.57079 0.4" type="hinge" />
						<body name="1_r_upper_arm_roll_link" pos="0 0 0">
							<geom fromto="-0.1 0 0 0.1 0 0" name="1_upper_arm_roll" size="0.02" type="capsule" />
							<joint axis="1 0 0" damping="0.1" name="1_r_upper_arm_roll_joint" pos="0 0 0" range="-1.5 1.7" type="hinge" />
							<body name="1_r_upper_arm_link" pos="0 0 0">
								<geom fromto="0 0 0 0.4 0 0" name="1_upper_arm" size="0.06" type="capsule" />
								<body axisangle="0 1 0 -1.65" name="1_r_elbow_flex_link" pos="0.4 0 0">
									<geom fromto="0 -0.02 0 0.0 0.02 0" name="1_elbow_flex" size="0.06" type="capsule" />
									<joint axis="0 1 0" damping="0.1" name="1_r_elbow_flex_joint" pos="0 0 0" range="-0.6713 1.65" type="hinge" />
									<body name="1_r_forearm_roll_link" pos="0 0 0">
										<geom fromto="-0.1 0 0 0.1 0 0" name="1_forearm_roll" size="0.02" type="capsule" />
										<joint axis="1 0 0" damping=".1" limited="true" name="1_r_forearm_roll_joint" pos="0 0 0" range="-1.5 1.5" type="hinge" />
										<body name="1_r_forearm_link" pos="0 0 0">
											<geom fromto="0 0 0 0.291 0 0" name="1_forearm" size="0.05" type="capsule" />
											<body name="1_r_wrist_flex_link" pos="0.321 0 0">
												<geom fromto="0 -0.02 0 0 0.02 0" name="1_wrist_flex" size="0.01" type="capsule" />
												<joint axis="0 1 0" damping=".1" name="1_r_wrist_flex_joint" pos="0 0 0" range="-1.094 0" type="hinge" />
												<body name="1_r_wrist_roll_link" pos="0 0 0">
													<joint axis="1 0 0" damping="0.1" limited="true" name="1_r_wrist_roll_joint" pos="0 0 0" range="-1.5 1.5" type="hinge" />
													<geom conaffinity="1" name="1_sword_blade" pos="0.6 0.02 0.02" size="0.5 0.005 0.01" type="box" />
													<geom name="1_sword_tip" type="sphere" rgba="0.6 0.6 0.6 1" pos=" 1.1 0.02 0.02" size="0.008" conaffinity="1" />
													<geom conaffinity="1" name="1_sword_handle" pos="0.1 0.02 0.02" size="0.1 0.02 0.02" type="box" />
												</body>
											</body>
										</body>
									</body>
								</body>
							</body>
						</body>
					</body>
				</body>
			</body>
		</body>
		<!-- </body> -->
	</worldbody>
	<actuator>
		<!-- <motor ctrllimited="true" ctrlrange="-2.0 2.0" joint="0_x_slide_joint"></motor> -->
		<motor ctrllimited="true" ctrlrange="-2.0 2.0" joint="0_y_slide_joint" />
		<motor ctrllimited="true" ctrlrange="-2.0 2.0" joint="0_r_shoulder_pan_joint" />
		<motor ctrllimited="true" ctrlrange="-2.0 2.0" joint="0_r_shoulder_lift_joint" />
		<motor ctrllimited="true" ctrlrange="-2.0 2.0" joint="0_r_shoulder_turn_joint" />
		<motor ctrllimited="true" ctrlrange="-2.0 2.0" joint="0_r_upper_arm_roll_joint" />
		<motor ctrllimited="true" ctrlrange="-2.0 2.0" joint="0_r_elbow_flex_joint" />
		<motor ctrllimited="true" ctrlrange="-2.0 2.0" joint="0_r_forearm_roll_joint" />
		<motor ctrllimited="true" ctrlrange="-2.0 2.0" joint="0_r_wrist_flex_joint" />
		<motor ctrllimited="true" ctrlrange="-2.0 2.0" joint="0_r_wrist_roll_joint" />
		<!-- <motor ctrllimited="true" ctrlrange="-2.0 2.0" joint="1_x_slide_joint"></motor> -->
		<motor ctrllimited="true" ctrlrange="-2.0 2.0" joint="1_y_slide_joint" />
		<motor ctrllimited="true" ctrlrange="-2.0 2.0" joint="1_r_shoulder_pan_joint" />
		<motor ctrllimited="true" ctrlrange="-2.0 2.0" joint="1_r_shoulder_lift_joint" />
		<motor ctrllimited="true" ctrlrange="-2.0 2.0" joint="1_r_shoulder_turn_joint" />
		<motor ctrllimited="true" ctrlrange="-2.0 2.0" joint="1_r_upper_arm_roll_joint" />
		<motor ctrllimited="true" ctrlrange="-2.0 2.0" joint="1_r_elbow_flex_joint" />
		<motor ctrllimited="true" ctrlrange="-2.0 2.0" joint="1_r_forearm_roll_joint" />
		<motor ctrllimited="true" ctrlrange="-2.0 2.0" joint="1_r_wrist_flex_joint" />
		<motor ctrllimited="true" ctrlrange="-2.0 2.0" joint="1_r_wrist_roll_joint" />
	</actuator>
	<contact>
		<pair geom1="0_sword_blade" geom2="1_sword_blade" name="blade_contact">
		</pair>
	</contact>
</mujoco>
