<mujoco model="arm3d">
  <compiler inertiafromgeom="true" angle="radian" coordinate="local"/>
  <option timestep="0.01" gravity="0 0 0" iterations="20" integrator="Euler" />

  <default>
    <joint armature='0.04' damping="1" limited="true"/>
    <geom friction=".8 .1 .1" density="300" margin="0.002" condim="1" contype="0" conaffinity="0"/>
  </default>

  <worldbody>
    <light diffuse=".5 .5 .5" pos="0 0 3" dir="0 0 -1"/>
    <geom name="table" type="plane" pos="0 0.5 -0.325" size="1 0.75 0.1" contype="1" conaffinity="1"/>
    <!-- <geom name="wall" rgba="1 0 0 1" type="box" pos="0 1. -0.325" size="1 0.03 1" contype="1" conaffinity="1"/> -->

    <body name="0_y_slide_link" pos="0 -0.4 0">
    <geom name="0_sp0" type="capsule" rgba="0.6 0.6 0.6 1" fromto="-0.1 0 -0.4 0.1 0 -0.4" size="0.1" />
    <joint name="0_y_slide" type="slide" pos="0 0 -0.4" axis="1 0 0" range="-1.0 1.0" />
    <body name="0_r_shoulder_pan_link" pos="0 0 0">
      <geom name="0_e1" type="sphere" rgba="0.6 0.6 0.6 1" pos="-0.06 0.05 0.2" size="0.05" conaffinity="1"/>
      <geom name="0_e2" type="sphere" rgba="0.6 0.6 0.6 1" pos=" 0.06 0.05 0.2" size="0.05" conaffinity="1"/>
      <geom name="0_e1p" type="sphere" rgba="0.1 0.1 0.1 1" pos="-0.06 0.09 0.2" size="0.03" conaffinity="1" />
      <geom name="0_e2p" type="sphere" rgba="0.1 0.1 0.1 1" pos=" 0.06 0.09 0.2" size="0.03" conaffinity="1"/>
      <geom name="0_e3" type="sphere" rgba="0.6 0.6 0.6 1" pos="-0.06 0.05 -0.2" size="0.05" conaffinity="1"/>
      <geom name="0_e4" type="sphere" rgba="0.6 0.6 0.6 1" pos=" 0.06 0.05 -0.2" size="0.05" conaffinity="1"/> 
      <geom name="0_sp" type="capsule" rgba="0.6 0.6 0.6 1" fromto="0 0 -0.4 0 0 0.2" size="0.1" conaffinity="1"/>
      <joint name="0_r_shoulder_pan_joint" type="hinge" pos="0 0 0" axis="0 0 1" range="-2.2854 1.714602" damping="1.0" />

      <body name="0_r_shoulder_lift_link" pos="0 0 0" axisangle="0 0 1 1.57079">
        <geom name="0_sl" type="capsule" fromto="0 -0.3 0 0 0.3 0" size="0.1" conaffinity="1"/>
        <joint name="0_r_shoulder_lift_joint" type="hinge" pos="0 0 0" axis="0 1 0" range="-0.5236 1.3963" damping="1.0" />

        <body name="0_r_upper_arm_roll_link" pos="0 -0.3 0">
          <geom name="0_uar" type="capsule" fromto="-0.1 0 0 0.1 0 0" size="0.02" conaffinity="1"/>
          <joint name="0_r_upper_arm_roll_joint" type="hinge" pos="0 0 0" axis="1 0 0" range="-1.5 1.7" damping="0.1" />

          <body name="0_r_upper_arm_link" pos="0 0 0">
            <geom name="0_ua" type="capsule" fromto="0 0 0 0.4 0 0" size="0.06" conaffinity="1"/>

            <body name="0_r_elbow_flex_link" pos="0.4 0 0">
              <geom name="0_ef" type="capsule" fromto="0 -0.02 0 0.0 0.02 0" size="0.06" conaffinity="1"/>
              <joint name="0_r_elbow_flex_joint" type="hinge" pos="0 0 0" axis="0 1 0" range="-2.3213 0" damping="0.1" />

              <body name="0_r_forearm_roll_link" pos="0 0 0">
                <geom name="0_fr" type="capsule" fromto="-0.1 0 0 0.1 0 0" size="0.02" />
                <joint name="0_r_forearm_roll_joint" type="hinge" limited="true" pos="0 0 0" axis="1 0 0" damping=".1" range="-1.5 1.5"/>

                <body name="0_r_forearm_link" pos="0 0 0">
                  <geom name="0_fa" type="capsule" fromto="0 0 0 0.291 0 0" size="0.05" conaffinity="1"/>

                  <body name="0_r_wrist_flex_link" pos="0.321 0 0">
                    <geom name="0_wf" type="capsule" fromto="0 -0.02 0 0 0.02 0" size="0.01" conaffinity="1"/>
                    <joint name="0_r_wrist_flex_joint" type="hinge" pos="0 0 0" axis="0 1 0" range="-1.094 0" damping=".1" />

                    <body name="0_r_wrist_roll_link" pos="0 0 0">
                      <joint name="0_r_wrist_roll_joint" type="hinge" pos="0 0 0" limited="true" axis="1 0 0" damping="0.1" range="-1.5 1.5"/>
                      <body name="0_tips_arm" pos="0 0 0">
                        <!-- <geom name="tip_arml" type="sphere" pos="0.1 -0.1 0." size="0.01" /> -->
                        <!--<body name="sword" pos="0.1 0 0.5" >  Adjust position as needed -->
                        <!--    <geom name="sword_blade" type="box" size="0.01 0.005 0.5" conaffinity="1"/>  Adjust size and shape as needed -->
                        <!--    <geom name="sword_handle" type="box" size="0.02 0.02 0.1"  pos="0 0 -0.5"/>  Handle, adjust position relative to blade -->
                        <!--</body> -->
                        <!-- <geom name="tip_armr" type="sphere" pos="0.1 0.1 0." size="0.01" /> -->
                      </body>
                      <geom name="0_sword_blade" type="box" size="0.5 0.005 0.01" pos="0.6 0.02 0.02" conaffinity="1"/>  <!-- Adjust size and shape as needed-->
                       <geom name= "0_sword_tip" type = "sphere" rgba="0.6 0.6 0.6 1" pos=" 1.1 0.02 0.02" size="0.008" conaffinity="1"/>
                      <geom name="0_sword_handle" type="box" size="0.1 0.02 0.02"  pos="0.1 0.02 0.02" conaffinity="1"/>  <!--Handle, adjust position relative to blade -->
                        
                      <!-- <geom type="capsule" fromto="0 -0.1 0. 0.0 +0.1 0" size="0.02" contype="1" conaffinity="1" />
                      <geom type="capsule" fromto="0 -0.1 0. 0.1 -0.1 0" size="0.02" contype="1" conaffinity="1" />
                      <geom type="capsule" fromto="0 +0.1 0. 0.1 +0.1 0." size="0.02" contype="1" conaffinity="1" /> -->
                    </body>
                  </body>
                </body>
              </body>
            </body>
          </body>
        </body>
      </body>
    </body>
    </body>

    <body name="1_y_slide_link" pos="0 1.4 0">
    <geom name="1_sp0" type="capsule" rgba="0.6 0.6 0.6 1" fromto="-0.1 0 -0.4 0.1 0 -0.4" size="0.1" conaffinity="1"/>
    <joint name="1_y_slide" type="slide" pos="0 0 -0.4" axis="1 0 0" range="-1.0 1.0" />
    <body name="1_r_shoulder_pan_link" pos="0 0 0" axisangle="0 0 1 -3.1415926">
      <geom name="1_e1" type="sphere" rgba="0.6 0.6 0.6 1" pos="-0.06 0.05 0.2" size="0.05" conaffinity="1"/>
      <geom name="1_e2" type="sphere" rgba="0.6 0.6 0.6 1" pos=" 0.06 0.05 0.2" size="0.05" conaffinity="1"/>
      <geom name="1_e1p" type="sphere" rgba="0.1 0.1 0.1 1" pos="-0.06 0.09 0.2" size="0.03" conaffinity="1"/>
      <geom name="1_e2p" type="sphere" rgba="0.1 0.1 0.1 1" pos=" 0.06 0.09 0.2" size="0.03" conaffinity="1"/>
      <geom name="1_e3" type="sphere" rgba="0.6 0.6 0.6 1" pos="-0.06 0.05 -0.2" size="0.05" conaffinity="1"/>
      <geom name="1_e4" type="sphere" rgba="0.6 0.6 0.6 1" pos=" 0.06 0.05 -0.2" size="0.05" conaffinity="1"/> 
      <geom name="1_sp" type="capsule" fromto="0 0 -0.4 0 0 0.2" size="0.1" />
      <joint name="1_r_shoulder_pan_joint" type="hinge" pos="0 0 0" axis="0 0 1" range="-2.2854 1.714602" damping="1.0" />

      <body name="1_r_shoulder_lift_link" pos="0 0 0" axisangle="0 0 1 1.57079">
        <geom name="1_sl" type="capsule" fromto="0 -0.3 0 0 0.3 0" size="0.1" conaffinity="1"/>
        <joint name="1_r_shoulder_lift_joint" type="hinge" pos="0 0 0" axis="0 1 0" range="-0.5236 1.3963" damping="1.0" />

        <body name="1_r_upper_arm_roll_link" pos="0 -0.3 0">
          <geom name="1_uar" type="capsule" fromto="-0.1 0 0 0.1 0 0" size="0.02" conaffinity="1"/>
          <joint name="1_r_upper_arm_roll_joint" type="hinge" pos="0 0 0" axis="1 0 0" range="-1.5 1.7" damping="0.1" />

          <body name="1_r_upper_arm_link" pos="0 0 0">
            <geom name="1_ua" type="capsule" fromto="0 0 0 0.4 0 0" size="0.06" conaffinity="1"/>

            <body name="1_r_elbow_flex_link" pos="0.4 0 0">
              <geom name="1_ef" type="capsule" fromto="0 -0.02 0 0.0 0.02 0" size="0.06" conaffinity="1"/>
              <joint name="1_r_elbow_flex_joint" type="hinge" pos="0 0 0" axis="0 1 0" range="-2.3213 0" damping="0.1" />

              <body name="1_r_forearm_roll_link" pos="0 0 0">
                <geom name="1_fr" type="capsule" fromto="-0.1 0 0 0.1 0 0" size="0.02" />
                <joint name="1_r_forearm_roll_joint" type="hinge" limited="true" pos="0 0 0" axis="1 0 0" damping=".1" range="-1.5 1.5"/>

                <body name="1_r_forearm_link" pos="0 0 0">
                  <geom name="1_fa" type="capsule" fromto="0 0 0 0.291 0 0" size="0.05" conaffinity="1"/>

                  <body name="1_r_wrist_flex_link" pos="0.321 0 0">
                    <geom name="1_wf" type="capsule" fromto="0 -0.02 0 0 0.02 0" size="0.01" conaffinity="1"/>
                    <joint name="1_r_wrist_flex_joint" type="hinge" pos="0 0 0" axis="0 1 0" range="-1.094 0" damping=".1" />

                    <body name="1_r_wrist_roll_link" pos="0 0 0">
                      <joint name="1_r_wrist_roll_joint" type="hinge" pos="0 0 0" limited="true" axis="1 0 0" damping="0.1" range="-1.5 1.5"/>
                      <body name="1_tips_arm" pos="0 0 0">
                        <!-- <geom name="tip_arml" type="sphere" pos="0.1 -0.1 0." size="0.01" /> -->
                        <!--<body name="sword" pos="0.1 0 0.5" >  Adjust position as needed -->
                        <!--    <geom name="sword_blade" type="box" size="0.01 0.005 0.5" conaffinity="1"/>  Adjust size and shape as needed -->
                        <!--    <geom name="sword_handle" type="box" size="0.02 0.02 0.1"  pos="0 0 -0.5"/>  Handle, adjust position relative to blade -->
                        <!--</body> -->
                        <!-- <geom name="tip_armr" type="sphere" pos="0.1 0.1 0." size="0.01" /> -->
                      </body>
                      <geom name="1_sword_blade" type="box" size="0.5 0.005 0.01" pos="0.6 0.02 0.02" conaffinity="1"/>  <!-- Adjust size and shape as needed-->
                      <geom name= "1_sword_tip" type = "sphere" rgba="0.6 0.6 0.6 1" pos=" 1.1 0.02 0.02" size="0.008" conaffinity="1"/>
                      <geom name="1_sword_handle" type="box" size="0.1 0.02 0.02"  pos="0.1 0.02 0.02" conaffinity="1"/>  <!--Handle, adjust position relative to blade -->
                        
                      <!-- <geom type="capsule" fromto="0 -0.1 0. 0.0 +0.1 0" size="0.02" contype="1" conaffinity="1" />
                      <geom type="capsule" fromto="0 -0.1 0. 0.1 -0.1 0" size="0.02" contype="1" conaffinity="1" />
                      <geom type="capsule" fromto="0 +0.1 0. 0.1 +0.1 0." size="0.02" contype="1" conaffinity="1" /> -->
                    </body>
                  </body>
                </body>
              </body>
            </body>
          </body>
        </body>
      </body>
    </body>
    </body>
  </worldbody>

  <actuator>
    <motor joint="0_y_slide" ctrlrange="-2.0 2.0" ctrllimited="true" />
    <motor joint="0_r_shoulder_pan_joint" ctrlrange="-2.0 2.0" ctrllimited="true" />
    <motor joint="0_r_shoulder_lift_joint" ctrlrange="-2.0 2.0" ctrllimited="true" />
    <motor joint="0_r_upper_arm_roll_joint" ctrlrange="-2.0 2.0" ctrllimited="true" />
    <motor joint="0_r_elbow_flex_joint" ctrlrange="-2.0 2.0" ctrllimited="true" />
    <motor joint="0_r_forearm_roll_joint" ctrlrange="-2.0 2.0" ctrllimited="true" />
    <motor joint="0_r_wrist_flex_joint" ctrlrange="-2.0 2.0" ctrllimited="true" />
    <motor joint="0_r_wrist_roll_joint" ctrlrange="-2.0 2.0" ctrllimited="true"/>
    <motor joint="1_y_slide" ctrlrange="-2.0 2.0" ctrllimited="true"  />
    <motor joint="1_r_shoulder_pan_joint" ctrlrange="-2.0 2.0" ctrllimited="true" />
    <motor joint="1_r_shoulder_lift_joint" ctrlrange="-2.0 2.0" ctrllimited="true" />
    <motor joint="1_r_upper_arm_roll_joint" ctrlrange="-2.0 2.0" ctrllimited="true" />
    <motor joint="1_r_elbow_flex_joint" ctrlrange="-2.0 2.0" ctrllimited="true" />
    <motor joint="1_r_forearm_roll_joint" ctrlrange="-2.0 2.0" ctrllimited="true" />
    <motor joint="1_r_wrist_flex_joint" ctrlrange="-2.0 2.0" ctrllimited="true" />
    <motor joint="1_r_wrist_roll_joint" ctrlrange="-2.0 2.0" ctrllimited="true"/>
  </actuator>
</mujoco>
